<?xml version="1.0"?><robot name="Climber">
  <link name="hand">
    <inertial>
      <origin xyz="0 0 0" />
      <mass value="1" />
      <inertia ixx="1e-3 " ixy="0" ixz="0" iyy="1e-3 " iyz="0" izz="1e-3 " />
    </inertial>

    <visual>
      <origin xyz="0 0 0" rpy="0 0 0" />
      <geometry>
        <sphere radius=".05" />
      </geometry>
      <material>
        <color rgba="1 0.647 0 1" />
      </material>
    </visual>

    <collision>
      <geometry>
        <sphere radius=".05" />
      </geometry>
    </collision>
  </link>

  <link name="arm0">
    <inertial>
      <origin xyz="0 0 -0.25" rpy="0 0 0" />
      <mass value="1" />
      <inertia ixx="1e-3 " ixy="0" ixz="0" iyy="1e-3 " iyz="0" izz="1e-3 " />
    </inertial>

    <visual>
      <origin xyz="0 0 -0.5" rpy="0 0 0" />
      <geometry>
        <sphere radius=".05" />
      </geometry>
      <material>
        <color rgba="0 0 0 1" />
      </material>
    </visual>

    <visual>
      <origin xyz="0 0 -0.25" rpy="0 0 0" />
      <geometry>
        <cylinder radius=".025" length="0.5"/>
      </geometry>
      <material>
        <color rgba="0.5 0.5 0.5 1" />
      </material>
    </visual>
  </link>

  <link name="arm1">
    <inertial>
      <origin xyz="0 0 -0.25" rpy="0 0 0" />
      <mass value="1" />
      <inertia ixx="1e-3 " ixy="0" ixz="0" iyy="1e-3 " iyz="0" izz="1e-3 " />
    </inertial>

    <visual>
      <origin xyz="0 0 -0.5" rpy="0 0 0" />
      <geometry>
        <sphere radius=".05" />
      </geometry>
      <material>
        <color rgba="0 0 0 1" />
      </material>
    </visual>

    <visual>
      <origin xyz="0 0 -0.25" rpy="0 0 0" />
      <geometry>
        <cylinder radius=".025" length="0.5"/>
      </geometry>
      <material>
        <color rgba="0.5 0.5 0.5 1" />
      </material>
    </visual>
  </link>

  <link name="arm2">
    <inertial>
      <origin xyz="0 0 -1" rpy="0 0 0" />
      <mass value="1" />
      <inertia ixx="1e-3 " ixy="0" ixz="0" iyy="1e-3 " iyz="0" izz="1e-3 " />
    </inertial>

    <visual>
      <origin xyz="0 0 -1" rpy="0 0 0" />
      <geometry>
        <sphere radius=".05" />
      </geometry>
      <material>
        <color rgba="0 0 0 1" />
      </material>
    </visual>

    <visual>
      <origin xyz="0 0 -0.5" rpy="0 0 0" />
      <geometry>
        <cylinder radius=".025" length="1"/>
      </geometry>
      <material>
        <color rgba="0.5 0.5 0.5 1" />
      </material>
    </visual>
  </link>
  
  <joint name="theta0" type="continuous">
    <parent link="hand" />
    <child link="arm0" />
    <axis xyz="0 -1 0" />
  </joint>

  <joint name="theta1" type="revolute">
    <origin xyz="0 0 -0.5" rpy="0 0 0"/>
    <parent link="arm0" />
    <child link="arm1" />
    <axis xyz="0 -1 0" />
    <limit effort="10000.0" lower="-2.7" upper="0.0" velocity="10000.0"/>
  </joint>

  <joint name="theta2" type="continuous">
    <origin xyz="0 0 -0.5" rpy="0 0 0"/>
    <parent link="arm1" />
    <child link="arm2" />
    <axis xyz="0 -1 0" />
  </joint>
  
  <transmission type="SimpleTransmission" name="theta1_force">
    <actuator name="force1" />
    <joint name="theta1" />
  </transmission>

  <transmission type="SimpleTransmission" name="theta2_force">
    <actuator name="force2" />
    <joint name="theta2" />
  </transmission>
  
  </robot>
</xml>